<!-- 
1. 错误被吃掉
throw new Error('error');
console.log(233333);
在这种情况下，因为 throw error 的缘故，代码被阻断执行，并不会打印 233333

let promise = new Promise(() => {
    throw new Error('error')
});
console.log(2333333);
这次会正常的打印 233333，说明 Promise 内部的错误不会影响到 Promise 外部的代码，而这种情况我们就通常称为 “吃掉错误”。

其实这并不是 Promise 独有的局限性，try..catch 也是这样，同样会捕获一个异常并简单的吃掉错误。
而正是因为错误被吃掉，Promise 链中的错误很容易被忽略掉，这也是为什么会一般推荐在 Promise 链的最后添加一个 catch 函数，
因为对于一个没有错误处理函数的 Promise 链，任何错误都会在链中被传播下去，直到你注册了错误处理函数。

2. 单一值
Promise 只能有一个完成值或一个拒绝原因，然而在真实使用的时候，往往需要传递多个值，一般做法都是构造一个对象或数组，
然后再传递，then 中获得这个值后，又会进行取值赋值的操作，每次封装和解封都无疑让代码变得笨重。
说真的，并没有什么好的方法，建议是使用 ES6 的解构赋值：
Promise.all([Promise.resolve(1), Promise.resolve(2)])
.then(([x, y]) => {
    console.log(x, y);
});

3. 无法取消
Promise 一旦新建它就会立即执行，无法中途取消。

4. 无法得知 pending 状态
当处于 pending 状态时，无法得知目前进展到哪一个阶段（刚刚开始还是即将完成）。

 -->